<?xml version="1.0"?>
<robot xmlns:xacro="http://www.ros.org/wiki/xacro">

    <!-- This file is not a robot in and of itself, it just contains some useful tags that could be included in any robot -->


    <!-- Specify some colours -->

    <material name="white">
        <color rgba="1 1 1 1"/>
    </material>

    <material name="orange">
        <color rgba="1 0.3 0.1 1"/>
    </material>

    <material name="blue">
        <color rgba="0.2 0.2 1 1"/>
    </material>



    <!-- Specify some standard inertial calculations https://en.wikipedia.org/wiki/List_of_moments_of_inertia -->
    <!-- These make use of xacro's mathematical functionality -->

    <xacro:macro name="inertial_sphere" params="mass radius *origin">
        <inertial>
            <xacro:insert_block name="origin"/>
            <mass value="${mass}" />
            <inertia ixx="${(2/5) * mass * (radius*radius)}" ixy="0.0" ixz="0.0" iyy="${(2/5) * mass * (radius*radius)}" iyz="0.0" izz="${(2/5) * mass * (radius*radius)}" />
        </inertial>
    </xacro:macro>


    <xacro:macro name="inertial_box" params="mass x y z *origin">
        <inertial>
            <xacro:insert_block name="origin"/>
            <mass value="${mass}" />
            <inertia ixx="${(1/12) * mass * (y*y+z*z)}" ixy="0.0" ixz="0.0" iyy="${(1/12) * mass * (x*x+z*z)}" iyz="0.0" izz="${(1/12) * mass * (x*x+y*y)}" />
        </inertial>
    </xacro:macro>

    <xacro:macro name="inertial_cylinder" params="mass length radius *origin">
        <inertial>
            <xacro:insert_block name="origin"/>
            <mass value="${mass}" />
            <inertia ixx="${(1/12) * mass * (3*radius*radius + length*length)}" ixy="0.0" ixz="0.0" iyy="${(1/12) * mass * (3*radius*radius + length*length)}" iyz="0.0" izz="${(1/2) * mass * (radius*radius)}" />
        </inertial>
    </xacro:macro>


    <!-- Specify some standard links -->

    <xacro:macro name="wheel_link_macro" params="name wheel_width wheel_radius">
        <link name="${name}">
            <visual>
                <origin xyz="0 0 0" rpy="0 0 0"/>
                <geometry>
                    <cylinder length="${wheel_width}" radius="${wheel_radius}" />
                </geometry>
                <material name="blue">
                    <color rgba="0.2 0.2 1 1"/>
                </material>
            </visual>
            <collision>
                <origin xyz="0 0 0" rpy="0 0 0"/>
                <geometry>
                    <cylinder length="${wheel_width}" radius="${wheel_radius}" />
                </geometry>
            </collision>
            <xacro:inertial_cylinder mass="1.0" length="${wheel_width}" radius="${wheel_radius}">
                <origin xyz="0 0 0" rpy="0 0 0"/>
            </xacro:inertial_cylinder>
        </link>
    </xacro:macro>

    <xacro:macro name="wheel_joint_macro" params="name parent child x y z">
        <joint name="${name}" type="continuous">
            <parent link="${parent}"/>
            <child link="${child}"/>
            <origin xyz="${x} ${y} ${z}" rpy="0 ${pi/2} 0"/>
            <axis xyz="0 0 1" rpy="0 0 0"/>
        </joint>
    </xacro:macro>

    <xacro:macro name="motor_link_macro" params="name motor_length motor_width motor_height x z ">
        <link name="${name}">
            <visual>
                <origin xyz="${x} 0 ${z}" rpy="0 0 0"/>
                <geometry>
                    <box size="${motor_length} ${motor_width} ${motor_height}" />
                </geometry>
                <material name="orange">
                    <color rgba="1 0.3 0.1 1"/>
                </material>
            </visual>
            <collision>
                <origin xyz="0 0 0" rpy="0 0 0"/>
                <geometry>
                    <box size="${motor_length} ${motor_width} ${motor_height}" />
                </geometry>
            </collision>
            <xacro:inertial_box mass="0.5" x="0.5" y="0.25" z="0.15">
                <origin xyz="0 0 0.075" rpy="0 0 0"/>
            </xacro:inertial_box>
        </link>
    </xacro:macro>

    <xacro:macro name="motor_joint_macro" params="name child x y z yy">
        <joint name="${name}" type="fixed">
            <parent link="chassis_link"/>
            <child link="${child}"/>
            <origin xyz="${x} ${y} ${z}" rpy="0 0 ${yy}"/>
        </joint>
    </xacro:macro>
</robot>